### 异步异常处理

```javascript
//下面方式 捕捉不到 异步异常处理
function func1 () {
  console.log('func1 run');
  func2()
}

function func2 () {
  try {
    console.log('func2 run');

    func3()
  } catch (error) {
    throw Error(' func2 error')
  }
}

function func3 () {
  console.log('func3 run');
  setTimeout(() => {
    throw Error('func3 error')
  }, 1000)
}

func1()
```
### 通过async和await 解决异步异常

```javascript
/**
 * 
 * await 返回的是promise 对表达式求值
 * 如果在一个函数调用链中有异步操作，必须加上await
 * **/
async function func1 () {
  console.log('func1 run');
  await func2()
}

async function func2 () {
  try {
    console.log('func2 run');
    await func3()
  } catch (error) {
    throw Error(' func2 error')
  }
}

function func3 () {
  console.log('func3 run');
  return new Promise((resolve, reject) => {
    setTimeout(() => {
      reject()
    }, 1000)
  })
}

func1()
```

### 
```javascript
//监听到异常
const router = new Router()

router.get('/v1/classic/latest', async (ctx, next) => {
  ctx.body = {
    key: "classic"
  }
})
router.post('/v1/:id/classic/detail', async (ctx, next) => {
  const params = ctx.params
  const query = ctx.request.query
  const header = ctx.request.header
  const body = ctx.request.body

  ctx.body = {
    key: "classic"
  }
  //抛出异常 
  throw new Error('api error')
})
module.exports = router
```
### 全局异常处理
```javascript
//全局异常处理 中间件就是一个函数，接受两个参数contenxt，next
//能监听到全局所有异常，因为可以结合洋葱模型,要最新app.use .app.use 的顺序要结合中间件的功能进行不同的处理
// 进入--->内部逻辑--->出来
const catchError = async (ctx, next) => {
  try {
    await next()
  } catch (error) {
    ctx.body = "服务器有点问题"
  }
}

module.exports = catchError

//
app.use(catchError)
```

### 定义错误返回格式
```javascript
//全局异常处理 中间件就是一个函数，接受两个参数contenxt，next

/**
 * 期刊
 */

const Router = require('koa-router')


const router = new Router()

router.get('/v1/classic/latest', async (ctx, next) => {
  ctx.body = {
    key: "classic"
  }
})
router.post('/v1/:id/classic/detail', async (ctx, next) => {
  const params = ctx.params
  const query = ctx.request.query
  const header = ctx.request.header
  const body = ctx.request.body
  console.log(query)
  if (true) {
    //动态语言可以随意修改属性
    const error = new Error('为什么错误')
    error.errorCode = 10001
    error.status = 400
    error.requestUrl = `${ctx.method} ${ctx.path}`
    throw error;
  }

  ctx.body = {
    key: "classic"
  }
})
module.exports = router
```

```javascript
const catchError = async (ctx, next) => {
  try {
    await next()
  } catch (error) {
    // error 堆栈调用信息
    // error 简化清晰明了的信息 给前端
    // koa 有状态码
    ctx.body = error
    // message
    // error_code 详细 开发者自己定义
    // request_url 当前请求的url
    // 错误的分类：已知错误，未知错误


    if (error.errorCode) {
      //已经错误
      ctx.body = {
        msg: error.message,
        error_code: error.errorCode,
        request: error.requestUrl
      }
      ctx.status = error.status
    } else {
      //未知错误

    }
  }
}

module.exports = catchError
```

### 定义HttpException异常基类

```javascript
/**
 * 异常处理基类,继承Error，因为要通过throw 抛出实例
 */

class HttpException extends Error {
  constructor(msg = '服务器异常', errorCode = 10000, code = 400) {
    super()
    this.errorCode = errorCode
    this.code = code
    this.msg = msg
  }
}

module.exports = {
  HttpException
}
```

```javascript
/**
 * 期刊
 */

const Router = require('koa-router')


const router = new Router()
const { HtppException } = require('../../../core/http-exception')

router.get('/v1/classic/latest', async (ctx, next) => {
  ctx.body = {
    key: "classic"
  }
})
router.post('/v1/:id/classic/detail', async (ctx, next) => {
  const params = ctx.params
  const query = ctx.request.query
  const header = ctx.request.header
  const body = ctx.request.body
  console.log(query)
  // if (true) {
  //   //动态语言可以随意修改属性
  //   const error = new Error('为什么错误')
  //   error.errorCode = 10001
  //   error.status = 400
  //   error.requestUrl = `${ctx.method} ${ctx.path}`
  //   throw error;
  // }
  if (true) {
    const error = new HtppException('为什么错误', 10001, 400)
    throw error;
  }

  ctx.body = {
    key: "classic"
  }
})
module.exports = router
```

```javascript
//全局异常处理 中间件就是一个函数，接受两个参数contenxt，next
const { HttpException } = require("../core/http-exception")
const catchError = async (ctx, next) => {
  try {
    await next()
  } catch (error) {
    if (error instanceof HttpException) {
      //一直错误
      ctx.body = {
        msg: error.message,
        error_code: error.errorCode,
        request: `${ctx.method} ${ctx.path}`
      }
      ctx.status = error.code
    }
  }
}

module.exports = catchError
```